Workbook

Sheet Portada
A1: ESPECIFICACIÓN DE REQUERIMIENTOS DE SOFTWARE (SRS)
A2: Plataforma de componentes transversales (TR)
A3: Conjunto de servicios, librerías y aplicaciones compartidas sobre los que se construyen los nueve productos (SazónPOS, PsicoAgenda, TurnoFácil, LibroPOS, GymControl, ClínicaNet, DocuFlujo, MercaWeb y JurisFlujo). Provee la estructura organizacional multi-tenant, la seguridad con permisos por alcance, catálogos, parámetros, correlativos, personas, identidad DNI/RUC, facturación electrónica, pagos, notificaciones, archivos, auditoría, eventos de dominio, reportes, IA, observabilidad, centro de soporte, gestor de contenidos web, portal del cliente final, integración externa y el agente local (edge). Se implementa como módulos NestJS 11 del monolito modular (hexagonal), librerías Angular 19 del monorepo Nx, esquemas PostgreSQL (Supabase) con RLS por tenant, Redis/BullMQ y Socket.IO.
A5: Versión | B5: 1.0 — Base para el SDD
A6: Fecha | B6: 10 de octubre de 2026
A7: Autor | B7: Israel Lozano (IsLozanDev) — Arquitectura y desarrollo
A8: Stack | B8: Backend NestJS 11 (monolito modular, hexagonal) · Frontend Angular 19 en monorepo Nx · PostgreSQL (Supabase) con RLS · Redis/BullMQ
A9: Documentos relacionados | B9: Definición de Producto y Arquitectura v1.2 · Componentes Transversales · Guía de Arquitectura de Código Backend · Plataforma de Operación
A11: Resumen
A12: Aplicaciones (frontends Nx) | B12: =COUNTA(Aplicaciones!A:A)-3 -> 5
A13: Módulos | B13: =COUNTA(Módulos!A:A)-3 -> 21
A14: Actores | B14: =COUNTA(Actores!A:A)-3 -> 18
A15: Procesos de negocio | B15: =COUNTA(Procesos!A:A)-3 -> 13
A16: Reglas de negocio | B16: =COUNTA('Reglas de negocio'!A:A)-3 -> 48
A17: Requerimientos funcionales (RF) | B17: =COUNTA(RF!A:A)-3 -> 138
A18: RF prioridad Must | B18: =COUNTIF(RF!M:M,"Must") -> 97
A19: RF de la fase MVP | B19: =COUNTIF(RF!N:N,"MVP") -> 110
A20: Criterios de aceptación (GWT) | B20: =COUNTA('Criterios GWT'!A:A)-3 -> 338
A21: RNF propios del sistema | B21: =COUNTIF(RNF!B:B,"Propio") -> 28
A22: RNF heredados de la plataforma | B22: =COUNTIF(RNF!B:B,"Plataforma") -> 30
A23: Componentes transversales utilizados | B23: =COUNTIF(Componentes!C:C,"<>")-1 -> 21
A25: Contenido del libro
A26: Aplicaciones | B26: Frontends Angular del sistema (apps del monorepo Nx), tipo, usuarios
A27: Módulos | B27: Módulos funcionales y la aplicación donde viven
A28: Actores | B28: Actores internos, externos y sistemas externos
A29: Procesos | B29: Procesos de negocio con disparador, pasos y resultado
A30: Reglas de negocio | B30: Reglas de negocio, cálculo, validación y normativas
A31: RF | B31: Requerimientos funcionales de bajo nivel: flujo, datos, permisos, reglas, trazas
A32: Criterios GWT | B32: Criterios de aceptación atómicos DADO QUE / CUANDO / ENTONCES, con estado de prueba
A33: RNF | B33: Requerimientos no funcionales (ISO/IEC 25010:2023): propios y heredados de la plataforma
A34: Matriz Proceso-RF | B34: Trazabilidad procesos × requerimientos funcionales
A35: Matriz RF-RNF | B35: Trazabilidad requerimientos funcionales × no funcionales
A36: Trazabilidad | B36: Vista plana proceso → RF → RNF → criterios → componentes (para importar al SDD)
A37: Componentes | B37: Matriz de componentes transversales y núcleos que el sistema usa, integra o extiende
A38: Consumidores | B38: Matriz componente × sistema consumidor
A40: Convenciones
A41: Prioridad (MoSCoW) | B41: Must = imprescindible para salir · Should = importante · Could = deseable · Won't = fuera de esta versión
A42: Fase | B42: MVP = primera versión vendible · R2 = segunda entrega · R3 = tercera entrega
A43: Tipo de criterio | B43: Positivo = camino feliz · Negativo = entrada inválida o regla incumplida · Borde = límite o concurrencia
A44: Criterio GWT atómico | B44: DADO QUE [contexto/precondición] · CUANDO [una acción del actor] · ENTONCES [resultado observable y verificable]
...

Sheet Aplicaciones
A1: Aplicaciones del sistema (frontends y servicios)
A2: Cada aplicación es un proyecto del monorepo Nx; comparten librerías comunes.
A3: ID | B3: Aplicación | C3: Tipo | D3: Tecnología / proyecto Nx | E3: Usuarios | F3: Descripción | G3: N.° RF
A4: APP-01 | B4: Consola de plataforma | C4: Backoffice web | D4: Angular 19 · app Nx plataforma-consola | E4: Administrador de plataforma, agente de soporte | F4: Consola del equipo dueño de la plataforma: tenants y suscripciones, catálogos globales y tablas maestras, facturación a clientes, centro de soporte, observabilidad y salud por cliente, eventos fallidos e integridad de auditoría. | G4: =COUNTIF(RF!C:C,"APP-01*") -> 23
A5: APP-02 | B5: Administración del cliente (embebible) | C5: Backoffice web | D5: Angular 19 · librería Nx plataforma-admin-cliente (rutas lazy embebidas en <cod>-backoffice) | E5: Administrador del cliente, encargado de facturación, editor de contenidos, oficial de datos personales | F5: Módulo de administración que cada producto monta en su backoffice: empresas, sucursales y unidades, usuarios, roles y perfiles, parámetros, catálogos propios, series, configuración de facturación y pagos, plantillas, CMS del sitio público, auditoría y derechos ARCO. | G5: =COUNTIF(RF!C:C,"APP-02*") -> 43
A6: APP-03 | B6: API de servicios de plataforma | C6: Servicio | D6: NestJS 11 · módulos transversales del monolito modular + workers BullMQ | E6: Módulos de producto, workers, integradores externos | F6: Puertos y adaptadores de los componentes TR expuestos como API interna (inyección de módulos NestJS), REST /v1 y eventos de dominio; incluye los workers de emisión de comprobantes, mensajes, reportes, despacho de eventos y evaluación de alertas. | G6: =COUNTIF(RF!C:C,"APP-03*") -> 55
A7: APP-04 | B7: Agente local (edge) | C7: Servicio | D7: Node.js 22 LTS · app Nx plataforma-edge (instalador Windows/Linux, SQLite cifrado) | E7: Equipos del local del cliente (POS, kiosco, pantallas) | F7: Servicio instalado en el local para impresión térmica, cajón de dinero, dispositivos (biométrico, kiosko, pantallas), operación sin internet con cola local y sincronización con la nube. | G7: =COUNTIF(RF!C:C,"APP-04*") -> 4
A8: APP-05 | B8: Librerías Angular compartidas y shell del portal | C8: Servicio | D8: Angular 19 · librerías Nx ui-diseno, shell-backoffice, seguridad-cliente, portal-shell, soporte-widget | E8: Usuarios internos de los productos y clientes finales en los <cod>-web | F8: Sistema de diseño, shell de backoffice (selector de sucursal, menú por permisos, notificaciones), cliente de seguridad OIDC, shell del portal del cliente final (registro, OTP, perfil, consentimientos) y widget de soporte con contexto automático. | G8: =COUNTIF(RF!C:C,"APP-05*") -> 13

Sheet Módulos
A1: Módulos funcionales
A3: ID | B3: Módulo | C3: Aplicación | D3: Descripción | E3: N.° RF
A4: MOD-01 | B4: Organización y suscripciones (TR-ORG) | C4: APP-01 · Consola de plataforma | D4: Tenant, empresa, sucursal, unidad operativa, suscripción por producto, límites y facturación de la plataforma. | E4: =COUNTIF(RF!B:B,"MOD-01*") -> 7
A5: MOD-02 | B5: Seguridad y accesos (TR-SEG) | C5: APP-02 · Administración del cliente (embebible) | D5: Manifiesto funcional, usuarios, membresías, roles, perfiles, asignaciones con alcance, permisos efectivos, MFA, sesiones y acceso de soporte. | E5: =COUNTIF(RF!B:B,"MOD-02*") -> 14
A6: MOD-03 | B6: Catálogos y tablas maestras (TR-CAT) | C6: APP-01 · Consola de plataforma | D6: Catálogos globales, mixtos y por tenant, ítems con vigencia, personalización por tenant, tablas oficiales y feriados. | E6: =COUNTIF(RF!B:B,"MOD-03*") -> 8
A7: MOD-04 | B7: Parámetros jerárquicos (TR-CFG) | C7: APP-02 · Administración del cliente (embebible) | D7: Definición, valores por alcance, resolución con herencia e historial de parámetros. | E7: =COUNTIF(RF!B:B,"MOD-04*") -> 5
A8: MOD-05 | B8: Correlativos y series (TR-SEQ) | C8: APP-02 · Administración del cliente (embebible) | D8: Series por alcance, numeración atómica, reinicio por periodo y bloques para operación offline. | E8: =COUNTIF(RF!B:B,"MOD-05*") -> 4
A9: MOD-06 | B9: Personas (TR-PER) | C9: APP-03 · API de servicios de plataforma | D9: Maestro de personas naturales y jurídicas por tenant, contactos, direcciones, roles por producto, duplicados y consentimientos. | E9: =COUNTIF(RF!B:B,"MOD-06*") -> 5
A10: MOD-07 | B10: Identidad e interoperabilidad (TR-IDN) | C10: APP-03 · API de servicios de plataforma | D10: Validación y consulta DNI/RUC con caché, proveedores, cuota y bitácora; identidad portable autorizada por el titular. | E10: =COUNTIF(RF!B:B,"MOD-07*") -> 8
A11: MOD-08 | B11: Facturación electrónica (TR-FE) | C11: APP-03 · API de servicios de plataforma | D11: Emisor, comprobantes UBL 2.1, envío a PSE/OSE, CDR, resumen diario, baja, contingencia, PDF y monitoreo. | E11: =COUNTIF(RF!B:B,"MOD-08*") -> 13
A12: MOD-09 | B12: Pagos y conciliación (TR-PAG) | C12: APP-03 · API de servicios de plataforma | D12: Pasarelas, intención de cobro, Yape/Plin, links de pago, webhooks, reembolsos, recurrencia y conciliación. | E12: =COUNTIF(RF!B:B,"MOD-09*") -> 9
A13: MOD-10 | B13: Notificaciones (TR-NOT) | C13: APP-03 · API de servicios de plataforma | D13: Plantillas multicanal, envío transaccional, recordatorios, preferencias, plantillas WhatsApp y estados de entrega. | E13: =COUNTIF(RF!B:B,"MOD-10*") -> 6
A14: MOD-11 | B14: Archivos (TR-ARC) | C14: APP-03 · API de servicios de plataforma | D14: Carga validada, versiones, URLs firmadas, retención y bloqueo legal. | E14: =COUNTIF(RF!B:B,"MOD-11*") -> 4
A15: MOD-12 | B15: Auditoría y datos personales (TR-AUD) | C15: APP-03 · API de servicios de plataforma | D15: Auditoría inmutable, accesos sensibles, integridad, solicitudes ARCO e incidentes de seguridad. | E15: =COUNTIF(RF!B:B,"MOD-12*") -> 8
A16: MOD-13 | B16: Eventos de dominio (TR-EVT) | C16: APP-03 · API de servicios de plataforma | D16: Outbox transaccional, catálogo de eventos, despacho a suscriptores, reintentos y cola de eventos fallidos. | E16: =COUNTIF(RF!B:B,"MOD-13*") -> 4
A17: MOD-14 | B17: Reportes y tableros (TR-REP) | C17: APP-03 · API de servicios de plataforma | D17: Definición declarativa de reportes, ejecución y exportación, programación de envíos y tableros por rol. | E17: =COUNTIF(RF!B:B,"MOD-14*") -> 4
A18: MOD-15 | B18: Servicios de IA (TR-IA) | C18: APP-03 · API de servicios de plataforma | D18: Pasarela de modelos, enmascaramiento, extracción documental, RAG, agente conversacional, copiloto analítico y control de consumo. | E18: =COUNTIF(RF!B:B,"MOD-15*") -> 6
A19: MOD-16 | B19: Observabilidad (TR-OBS) | C19: APP-01 · Consola de plataforma | D19: Indicadores de negocio por minuto, reglas de alerta, evaluación, salud por tenant y sucursal. | E19: =COUNTIF(RF!B:B,"MOD-16*") -> 5
A20: MOD-17 | B20: Centro de soporte (TR-SOP) | C20: APP-01 · Consola de plataforma | D20: Tickets con contexto, SLA por plan, ciclo de vida, escalamiento, problemas en GitHub y base de conocimiento. | E20: =COUNTIF(RF!B:B,"MOD-17*") -> 8
A21: MOD-18 | B21: Gestor de contenidos web (TR-CMS) | C21: APP-02 · Administración del cliente (embebible) | D21: Sitio público por tenant: dominio, marca, páginas por bloques, menús, medios, noticias, SEO, formularios y versiones. | E21: =COUNTIF(RF!B:B,"MOD-18*") -> 6
A22: MOD-19 | B22: Portal del cliente final (TR-POR) | C22: APP-05 · Librerías Angular compartidas y shell del portal | D22: Registro y acceso de clientes externos, perfil, consentimientos y vista consolidada de transacciones. | E22: =COUNTIF(RF!B:B,"MOD-19*") -> 5
A23: MOD-20 | B23: Integración externa (TR-INT) | C23: APP-03 · API de servicios de plataforma | D23: Clientes de API, API pública versionada, webhooks salientes y sincronización con bases institucionales. | E23: =COUNTIF(RF!B:B,"MOD-20*") -> 4
A24: MOD-21 | B24: Agente local (TR-EDGE) | C24: APP-04 · Agente local (edge) | D24: Enrolamiento, impresión térmica, cajón, cola offline, sincronización, dispositivos y actualización remota. | E24: =COUNTIF(RF!B:B,"MOD-21*") -> 5

Sheet Actores
A1: Actores
A3: ID | B3: Actor | C3: Tipo | D3: Descripción
A4: ACT-01 | B4: Administrador de plataforma | C4: Interno | D4: Integrante del equipo dueño de la plataforma; da de alta clientes, gestiona suscripciones, catálogos globales y operación.
A5: ACT-02 | B5: Agente de soporte (N1/N2) | C5: Interno | D5: Atiende tickets de los clientes de los nueve productos; N2 analiza causa raíz y coordina con ingeniería.
A6: ACT-03 | B6: Administrador del cliente | C6: Interno | D6: Usuario propietario o administrador del tenant; configura empresas, sucursales, usuarios, roles y parámetros.
A7: ACT-04 | B7: Usuario operativo del producto | C7: Interno | D7: Cajero, recepcionista, mozo, operador de ventanilla o asistente que usa un producto apoyado en la plataforma.
A8: ACT-05 | B8: Cliente final / titular de datos | C8: Externo | D8: Persona natural o jurídica atendida por un tenant (cliente, paciente, socio, administrado) y titular de sus datos personales.
A9: ACT-06 | B9: Encargado de facturación del cliente | C9: Interno | D9: Contador o asistente que configura el emisor electrónico y monitorea comprobantes y conciliaciones.
A10: ACT-07 | B10: Editor de contenidos web | C10: Interno | D10: Usuario del cliente que administra páginas, noticias, banners y SEO del sitio público.
A11: ACT-08 | B11: Módulo de producto consumidor | C11: Sistema externo | D11: Módulo NestJS de un producto (rest, psi, col, lib, gym, cli, doc, eco, lex) o núcleo que invoca los puertos de la plataforma.
A12: ACT-09 | B12: PSE/OSE y SUNAT | C12: Sistema externo | D12: Proveedor de servicios electrónicos u operador de servicios electrónicos que valida y envía comprobantes a SUNAT y devuelve el CDR.
A13: ACT-10 | B13: Pasarela de pagos | C13: Sistema externo | D13: Procesador de tarjetas, billeteras Yape/Plin y links de pago que notifica por webhook firmado.
A14: ACT-11 | B14: Proveedor de identidad pública | C14: Sistema externo | D14: Convenio RENIEC o proveedor autorizado de consulta DNI y padrón RUC de SUNAT.
... A21: ACT-18 | B21: Responsable de datos personales del cliente | C21: Interno | D21: Persona designada por el tenant para atender derechos ARCO, consentimientos e incidentes ante la ANPD.

Sheet Procesos
A1: Procesos de negocio
A3: ID | B3: Proceso | C3: Descripción | D3: Actores | E3: Disparador | F3: Pasos | G3: Resultado | H3: N.° RF
A4: TR-P01 | B4: Alta y configuración de tenant | C4: Incorporación de un nuevo cliente: tenant, suscripción, empresa, sucursales, unidades y usuario administrador, hasta dejarlo operativo en su producto. | D4: Administrador de plataforma, Administrador del cliente, Proveedor de identidad OIDC (IdP), Proveedor de mensajería, Planificador de tareas | E4: Firma de contrato o registro de prueba gratuita | F4: 1. El administrador de plataforma inicia el asistente de alta con el nombre comercial y el producto contratado. 2. El sistema crea el tenant en estado PRUEBA o ACTIVO y la suscripción con plan y límites. 3. Se registra la empresa con su RUC validado contra el padrón y su sucursal principal (establecimiento 0000). 4. Se invita al administrador del cliente; el IdP crea la cuenta y el sistema la vincula como propietario. 5. El administrador del cliente completa sucursales, unidades operativas, parámetros y series. 6. El planificador controla vencimientos de prueba y suscripción y notifica antes del corte. | G4: Tenant activo con suscripción vigente, estructura organizacional y administrador con acceso | H4: =COUNTIF('Matriz Proceso-RF'!D:D,"●") -> 13
A5: TR-P02 | B5: Gestión de seguridad y accesos | C5: Administración de usuarios, membresías, roles, perfiles y asignaciones con alcance, incluido el acceso temporal del equipo de soporte. | D5: Administrador del cliente, Usuario operativo del producto, Proveedor de identidad OIDC (IdP), Agente de soporte (N1/N2), Módulo de producto consumidor | E5: Ingreso, cambio de puesto o salida de un colaborador; despliegue de una nueva versión de producto | F5: 1. El despliegue aplica el manifiesto del producto (módulos, opciones, permisos). 2. El administrador del cliente invita al usuario y le asigna un perfil o rol con alcance y vigencia. 3. El usuario acepta la invitación y se autentica en el IdP. 4. Al iniciar sesión elige empresa y sucursal; el sistema calcula permisos efectivos y menú. 5. Las acciones sensibles exigen MFA reciente y quedan auditadas. 6. Las asignaciones se revocan o vencen y las sesiones se cierran cuando corresponde. | G5: Usuarios con permisos efectivos acordes a su puesto y alcance, con trazabilidad completa | H5: =COUNTIF('Matriz Proceso-RF'!E:E,"●") -> 14
A6: TR-P03 | B6: Gestión de catálogos y parámetros | C6: Mantenimiento de catálogos globales y propios, tablas maestras oficiales, parámetros jerárquicos y series de numeración. | D6: Administrador de plataforma, Administrador del cliente, Módulo de producto consumidor | E6: Cambio normativo, nueva versión de tabla oficial o necesidad de configuración del cliente | F6: 1. El administrador de plataforma actualiza catálogos globales o importa la nueva versión de una tabla oficial. 2. El sistema publica catalogo.actualizado e invalida cachés. 3. El administrador del cliente ajusta ítems globales o registra ítems propios en catálogos mixtos. 4. El administrador del cliente define valores de parámetros por alcance y series por establecimiento. 5. Los productos resuelven catálogos, parámetros y correlativos mediante los puertos de la plataforma. | G6: Catálogos, parámetros y series vigentes y consistentes para todos los productos | H6: =COUNTIF('Matriz Proceso-RF'!F:F,"●") -> 19
A7: TR-P04 | B7: Emisión de comprobantes electrónicos | C7: Generación, firma, envío y seguimiento de comprobantes electrónicos SUNAT desde cualquier producto. | D7: Módulo de producto consumidor, Encargado de facturación del cliente, PSE/OSE y SUNAT, Cliente final / titular de datos, Planificador de tareas | E7: Un producto confirma una venta o un ajuste que requiere comprobante | F7: 1. El producto solicita la emisión con los datos de la venta y el tipo de comprobante. 2. El sistema valida adquirente, montos e impuestos y asigna serie y número. 3. Se genera el XML UBL 2.1, se firma con el certificado del emisor y se encola el envío. 4. El worker envía al PSE/OSE y procesa el CDR o la respuesta de error. 5. Las boletas se informan en resumen diario y las anulaciones con comunicación de baja o nota de crédito. 6. Se genera la representación impresa y se envía al cliente; los pendientes se monitorean hasta su estado final. | G7: Comprobante aceptado con CDR, PDF disponible y entregado al cliente, o incidencia gestionada | H7: =COUNTIF('Matriz Proceso-RF'!G:G,"●") -> 19
A8: TR-P05 | B8: Cobros y conciliación | C8: Cobro a clientes finales con medios electrónicos, confirmación por webhook, reembolsos, cobros recurrentes y conciliación con la liquidación de la pasarela; incluye el cobro de la suscripción del tenant. | D8: Módulo de producto consumidor, Usuario operativo del producto, Cliente final / titular de datos, Pasarela de pagos, Encargado de facturación del cliente, Administrador de plataforma | E8: Una venta, cita, membresía o pedido requiere cobro electrónico; cierre diario de liquidaciones | F8: 1. El producto crea una intención de cobro o un link de pago. 2. El cliente paga con tarjeta, Yape o Plin en la pasarela. 3. La pasarela notifica por webhook firmado; el sistema confirma el pago y publica pago.confirmado. 4. Los reembolsos se solicitan con motivo y se confirman por webhook. 5. Diariamente se importa la liquidación y se concilia contra los pagos registrados. | G8: Pagos confirmados, reembolsos registrados y diferencias de conciliación identificadas | H8: =COUNTIF('Matriz Proceso-RF'!H:H,"●") -> 13
A9: TR-P06 | B9: Envío de notificaciones | C9: Comunicación con clientes finales y usuarios internos por correo, SMS, WhatsApp y push, transaccional o programada. | D9: Módulo de producto consumidor, Administrador del cliente, Cliente final / titular de datos, Proveedor de mensajería, Planificador de tareas | E9: Un evento de negocio o un recordatorio programado requiere avisar a una persona | F9: 1. El producto solicita el envío indicando plantilla, destinatario y variables, o programa un recordatorio. 2. El sistema verifica preferencias, consentimiento y bajas del destinatario. 3. Renderiza la plantilla del canal y la entrega al proveedor de mensajería. 4. Recibe el estado de entrega; ante fallo reintenta o cambia de canal. 5. El destinatario gestiona sus preferencias o se da de baja. | G9: Mensaje entregado por el canal preferido o fallo registrado con reintento | H9: =COUNTIF('Matriz Proceso-RF'!I:I,"●") -> 11
A10: TR-P07 | B10: Gestión de contenidos web (CMS) | C10: Construcción y publicación del sitio público del tenant y del portal del cliente final. | D10: Editor de contenidos web, Administrador del cliente, Cliente final / titular de datos | E10: El cliente necesita publicar o actualizar su sitio, campañas o información | F10: 1. El administrador configura dominio o subdominio y la identidad de marca. 2. El editor crea páginas por bloques, menús, medios y noticias. 3. Previsualiza y publica de inmediato o programa la publicación. 4. El sitio se sirve por SSR con caché e invalidación al publicar. 5. Los visitantes envían formularios y se registran en el portal del cliente. | G10: Sitio publicado en su dominio con contenido vigente, SEO y formularios operativos | H10: =COUNTIF('Matriz Proceso-RF'!J:J,"●") -> 13
A11: TR-P08 | B11: Atención de soporte | C11: Gestión de tickets de los clientes de los nueve productos desde su registro hasta el cierre, con SLA por plan. | D11: Usuario operativo del producto, Administrador del cliente, Agente de soporte (N1/N2), GitHub, Planificador de tareas | E11: Un usuario reporta un incidente o consulta, o una alerta crea un ticket automático | F11: 1. El usuario crea un ticket desde el widget; el sistema adjunta contexto técnico y calcula prioridad y plazos. 2. El agente N1 analiza, responde y, si requiere, pide información al cliente (pausa de SLA). 3. Si no lo resuelve, escala a N2 y se vincula a un problema con issue en GitHub. 4. Al publicar la corrección se resuelve el problema y sus tickets. 5. El cliente confirma o el ticket se cierra automáticamente. | G11: Ticket resuelto dentro del SLA, problema raíz enlazado y cliente informado | H11: =COUNTIF('Matriz Proceso-RF'!K:K,"●") -> 10
A12: TR-P09 | B12: Observabilidad y alertas | C12: Medición de indicadores de negocio por cliente y sucursal, detección de anomalías y alerta temprana. | D12: Planificador de tareas, Administrador de plataforma, Agente de soporte (N1/N2), Administrador del cliente | E12: Eventos de dominio de los productos; ejecución programada del evaluador cada minuto | F12: 1. Los productos declaran indicadores en su manifiesto. 2. El consumidor de eventos registra la métrica por minuto. 3. El evaluador compara contra umbrales, ausencia de datos o línea base. 4. Abre o resuelve alertas, notifica y crea tickets si la regla lo indica. 5. El equipo revisa el tablero de salud por tenant y sucursal. | G12: Alertas abiertas y resueltas automáticamente, salud por cliente visible y tickets creados cuando corresponde | H12: =COUNTIF('Matriz Proceso-RF'!L:L,"●") -> 11
A13: TR-P10 | B13: Consulta de identidad e interoperabilidad | C13: Identificación de personas con DNI/RUC, maestro de personas compartido entre productos del tenant e identidad portable autorizada por el titular. | D13: Usuario operativo del producto, Módulo de producto consumidor, Proveedor de identidad pública, Cliente final / titular de datos | E13: Registro de un cliente, paciente o socio, o emisión de un comprobante que requiere identificar al adquirente | F13: 1. El usuario digita el tipo y número de documento. 2. El sistema valida el formato y busca en caché; si no existe, consulta al proveedor con control de cuota. 3. Registra o reutiliza la persona del tenant y le asigna el rol del producto. 4. Si el titular tiene identidad portable, el tenant solicita autorización y el titular la confirma con un código. 5. El sistema entrega solo los campos autorizados y registra cada acceso. | G13: Persona identificada con datos de fuente oficial y, si el titular autoriza, datos portables incorporados | H13: =COUNTIF('Matriz Proceso-RF'!M:M,"●") -> 17
A14: TR-P11 | B14: Auditoría y cumplimiento de datos personales (ARCO) | C14: Registro inmutable de operaciones críticas, atención de derechos ARCO, consentimientos e incidentes conforme a la Ley 29733. | D14: Administrador del cliente, Responsable de datos personales del cliente, Cliente final / titular de datos, Administrador de plataforma | E14: Operación crítica, acceso a dato sensible, solicitud del titular o incidente de seguridad | F14: 1. Los productos registran operaciones críticas y accesos sensibles en la auditoría. 2. El titular presenta una solicitud ARCO desde el portal o el tenant la registra. 3. El responsable compila los datos, decide y responde dentro del plazo legal. 4. Las cancelaciones anonimizan respetando plazos de conservación obligatoria. 5. Los incidentes se registran y se notifican a la ANPD y a los titulares cuando corresponde. | G14: Evidencia íntegra y verificable; solicitudes atendidas en plazo; incidentes notificados | H14: =COUNTIF('Matriz Proceso-RF'!N:N,"●") -> 23
A15: TR-P12 | B15: Integración externa y sincronización | C15: Intercambio con sistemas de terceros y bases institucionales mediante eventos, API pública, webhooks y el agente local. | D15: Módulo de producto consumidor, Sistema institucional o integrador, Planificador de tareas, Administrador de plataforma, Usuario operativo del producto | E15: Cambio de un agregado de negocio, solicitud de un integrador o recuperación de conectividad del local | F15: 1. El módulo de producto publica el evento en el outbox dentro de su transacción. 2. El despachador entrega el evento a suscriptores internos y webhooks salientes. 3. Los conectores institucionales leen por cursor y confirman el último evento procesado. 4. El agente local sincroniza su cola offline y descarga configuración. 5. Se concilian conteos diarios y se reprocesan los eventos fallidos. | G15: Sistemas externos y locales sincronizados, con entrega confirmada y conciliación diaria | H15: =COUNTIF('Matriz Proceso-RF'!O:O,"●") -> 16
A16: TR-P13 | B16: Reportes y analítica | C16: Generación de reportes operativos y de gestión, tableros por rol y análisis asistido por IA. | D16: Administrador del cliente, Usuario operativo del producto, Encargado de facturación del cliente, Planificador de tareas, Proveedor de modelos de IA | E16: Necesidad de información de gestión o envío programado | F16: 1. El producto declara sus reportes y tableros en el manifiesto. 2. El usuario selecciona un reporte, define filtros y lo ejecuta o programa. 3. El motor aplica alcance y permisos, ejecuta la consulta y genera Excel o PDF. 4. Los reportes programados se envían por correo; el copiloto responde preguntas con consultas predefinidas. | G16: Reporte o tablero entregado con datos del alcance permitido al usuario | H16: =COUNTIF('Matriz Proceso-RF'!P:P,"●") -> 13

Sheet Reglas de negocio
A1: Reglas de negocio
A3: ID | B3: Regla | C3: Tipo | D3: Fuente
A4: TR-RN-001 | B4: Toda entidad de negocio pertenece a la jerarquía tenant → empresa (RUC) → sucursal (establecimiento) → unidad operativa y lleva tenant_id; ninguna consulta puede cruzar tenants. | C4: Negocio | D4: ADR de arquitectura multi-tenant; transversal/sql/01_org
A5: TR-RN-002 | B5: El RUC tiene 11 dígitos, inicia con 10, 15, 17 o 20 y su último dígito cumple el algoritmo módulo 11 de SUNAT; el DNI tiene 8 dígitos numéricos. | C5: Validación | D5: SUNAT (algoritmo de dígito verificador); RENIEC
A6: TR-RN-003 | B6: Cada empresa tiene exactamente una sucursal principal; el código de establecimiento SUNAT tiene 4 dígitos y el domicilio fiscal es 0000. | C6: Validación | D6: SUNAT — establecimientos anexos del RUC
A7: TR-RN-004 | B7: Una unidad operativa debe pertenecer a una sucursal, salvo las de tipo ALMACEN, que pueden pertenecer directamente a la empresa (almacén central). | C7: Validación | D7: transversal/sql/01_org (ck_unidad_sin_sucursal)
A8: TR-RN-005 | B8: Estados del tenant: PRUEBA → ACTIVO → SUSPENDIDO → BAJA. Un tenant SUSPENDIDO solo permite lectura, pago de deuda, exportación de datos y soporte; BAJA conserva los datos 90 días antes de su eliminación definitiva. | C8: Negocio | D8: Política comercial de la plataforma
A9: TR-RN-006 | B9: Un producto sin suscripción vigente (ACTIVA o PRUEBA) no otorga permisos; no se pueden crear sucursales ni usuarios por encima de los límites del plan. | C9: Negocio | D9: transversal/sql/02_seg (permisos_efectivos); contrato de suscripción
A10: TR-RN-007 | B10: Los permisos tienen el código producto.recurso.accion y se evalúan por alcance: TENANT cubre todas las empresas y sucursales; EMPRESA, sus sucursales y unidades; SUCURSAL, sus unidades; UNIDAD, solo esa unidad. Los permisos PLAT no dependen de suscripción. | C10: Negocio | D10: transversal/sql/02_seg
A11: TR-RN-008 | B11: Una asignación tiene un rol o un perfil, nunca ambos ni ninguno, y su alcance debe ser coherente con la empresa, sucursal o unidad informada; la vigencia hasta no puede ser anterior a la vigencia desde. | C11: Validación | D11: transversal/sql/02_seg (ck_asig_rol_o_perfil, ck_asig_alcance)
A12: TR-RN-009 | B12: Los permisos marcados como sensibles (anular, reembolsar, exportar datos personales, cambiar series, otorgar roles) exigen MFA con antigüedad máxima de 15 minutos y quedan auditados. | C12: Negocio | D12: TR-RNF-009; política de seguridad
A13: TR-RN-010 | B13: Todo tenant debe tener al menos un propietario con membresía ACTIVA; no se puede suspender, revocar ni dar de baja al último propietario. | C13: Negocio | D13: Política de seguridad de la plataforma
A14: TR-RN-011 | B14: El acceso del equipo de soporte a datos de un tenant requiere autorización expresa del administrador del cliente, con motivo, ticket asociado y vigencia máxima de 4 horas; cada acción se audita como ACCESO_SOPORTE. | C14: Negocio | D14: Ley 29733 (encargado de tratamiento); TR-RNF-013
... A51: TR-RN-048 | B51: Un incidente de seguridad que afecte datos personales se registra y se notifica a la Autoridad Nacional de Protección de Datos Personales dentro de las 48 horas de conocido. | C51: Normativa | D51: D.S. N.° 016-2024-JUS (verificar artículo)

Sheet RF
A1: Requerimientos funcionales
A2: Un requerimiento = una capacidad verificable. Los criterios de aceptación están en la hoja «Criterios GWT».
A3: ID | B3: Módulo | C3: Aplicación | D3: Nombre | E3: Descripción | F3: Actores | G3: Permiso | H3: Precondiciones | I3: Flujo básico | J3: Datos y validaciones | K3: Reglas | L3: Salida | M3: Prioridad | N3: Fase | O3: Procesos | P3: Componentes | Q3: RNF | R3: IA | S3: N.° criterios
A4: TR-RF-001 | B4: MOD-01 · Organización y suscripciones (TR-ORG) | C4: APP-01 · Consola de plataforma | D4: Dar de alta un tenant con asistente | E4: El sistema debe permitir al administrador de plataforma crear un tenant mediante un asistente que registra en una sola operación el tenant, la suscripción inicial, la empresa con su RUC, la sucursal principal y la invitación al propietario. | F4: Administrador de plataforma | G4: plat.tenant.crear | H4: El administrador de plataforma tiene sesión con MFA vigente y el producto contratado existe en seg.producto. | I4: 1. El actor ingresa código y nombre del tenant, producto, plan y modalidad (prueba o activo). 2. El actor ingresa RUC, razón social y correo del propietario. 3. El sistema valida el RUC (TR-RN-002) y consulta el padrón mediante TR-IDN para completar razón social y domicilio fiscal. 4. El sistema crea tenant, suscripción, empresa y sucursal principal con establecimiento 0000 en una transacción. 5. El sistema siembra parámetros por defecto, series iniciales y roles predefinidos del producto. 6. El sistema invita al propietario por correo y publica tenant.creado. | J4: codigo (texto 3-30, único, minúsculas y guiones); nombre (texto 3-150, obligatorio); producto_codigo (catálogo de productos, obligatorio); plan (BASICO|PRO|EMPRESA); modalidad (PRUEBA|ACTIVO); ruc (11 dígitos, obligatorio); correo_propietario (correo válido, obligatorio) | K4: TR-RN-001, TR-RN-002, TR-RN-003, TR-RN-005 | L4: Tenant en estado PRUEBA o ACTIVO con empresa, sucursal principal, suscripción y propietario invitado; tiempo total del asistente < 15 min | M4: Must | N4: MVP | O4: TR-P01 | P4: TR-ORG, TR-SEG, TR-IDN, TR-CFG, TR-SEQ, TR-NOT, TR-EVT | Q4: TR-RNF-029, TR-RNF-010, TR-RNF-008 | R4: No | S4: =COUNTIF('Criterios GWT'!B:B,A4) -> 3
A5: TR-RF-002 | B5: MOD-01 · Organización y suscripciones (TR-ORG) | C5: APP-02 · Administración del cliente (embebible) | D5: Registrar empresa del tenant | E5: El sistema debe permitir al administrador del cliente registrar empresas adicionales (RUC) dentro de su tenant, completando razón social, nombre comercial y domicilio fiscal desde el padrón RUC. | F5: Administrador del cliente | G5: plat.empresa.crear | H5: El tenant está ACTIVO o en PRUEBA y el actor tiene alcance TENANT. | I5: 1. El actor ingresa el RUC de la nueva empresa. 2. El sistema valida el formato y consulta el padrón mediante TR-IDN. 3. El sistema muestra razón social, estado y condición del contribuyente. 4. El actor completa nombre comercial y confirma. 5. El sistema crea la empresa y su sucursal principal con establecimiento 0000 y publica empresa.creada. | J5: ruc (11 dígitos, único por tenant); razon_social (texto 1-200, desde padrón); nombre_comercial (texto 0-150); direccion_fiscal (texto 0-250); ubigeo (6 dígitos, catálogo UBIGEO) | K5: TR-RN-001, TR-RN-002, TR-RN-003, TR-RN-019 | L5: Empresa activa con sucursal principal creada | M5: Must | N5: MVP | O5: TR-P01, TR-P10 | P5: TR-ORG, TR-IDN, TR-CAT, TR-EVT | Q5: TR-RNF-010, TR-RNF-007 | R5: No | S5: =COUNTIF('Criterios GWT'!B:B,A5) -> 3
A6: TR-RF-003 | B6: MOD-01 · Organización y suscripciones (TR-ORG) | C6: APP-02 · Administración del cliente (embebible) | D6: Registrar sucursal (establecimiento) | E6: El sistema debe permitir registrar, editar e inactivar sucursales de una empresa con su código de establecimiento SUNAT, dirección, ubigeo, teléfono y zona horaria, garantizando una sola sucursal principal por empresa. | F6: Administrador del cliente | G6: plat.sucursal.gestionar | H6: La empresa existe y está activa; la suscripción no ha alcanzado su límite de sucursales. | I6: 1. El actor selecciona la empresa y elige nueva sucursal. 2. Ingresa código interno, nombre, código de establecimiento SUNAT, dirección y ubigeo. 3. El sistema valida unicidad del código, formato del establecimiento y límite del plan. 4. El sistema guarda la sucursal y publica sucursal.creada. | J6: codigo (texto 1-20, único por empresa); nombre (texto 3-150); codigo_establecimiento_sunat (4 dígitos, opcional); direccion (texto 0-250); ubigeo (catálogo UBIGEO); telefono (texto 0-30); zona_horaria (IANA, por defecto America/Lima); es_principal (booleano) | K6: TR-RN-001, TR-RN-003, TR-RN-006 | L6: Sucursal activa disponible para asignaciones, series y parámetros | M6: Must | N6: MVP | O6: TR-P01 | P6: TR-ORG, TR-CAT, TR-EVT | Q6: TR-RNF-010, TR-RNF-027 | R6: No | S6: =COUNTIF('Criterios GWT'!B:B,A6) -> 3
A7: TR-RF-004 | B7: MOD-01 · Organización y suscripciones (TR-ORG) | C7: APP-02 · Administración del cliente (embebible) | D7: Registrar unidad operativa | E7: El sistema debe permitir registrar unidades operativas (almacén, caja, punto de venta, consultorio, ventanilla, salón, estación de producción) dentro de una sucursal, o almacenes centrales a nivel de empresa, con atributos propios del tipo. | F7: Administrador del cliente | G7: plat.unidad.gestionar | H7: Existe la sucursal o, si el tipo es ALMACEN, al menos la empresa. | I7: 1. El actor elige la sucursal y el tipo de unidad del catálogo TIPO_UNIDAD. 2. Ingresa código, nombre, unidad padre opcional y atributos. 3. El sistema valida la regla de pertenencia (TR-RN-004) y la unicidad por empresa, tipo y código. 4. El sistema guarda la unidad y publica unidad.creada. | J7: tipo (catálogo TIPO_UNIDAD, obligatorio); codigo (texto 1-20); nombre (texto 3-150); sucursal_id (uuid, obligatorio salvo ALMACEN); padre_id (uuid, opcional); atributos (JSON: impresora, capacidad, piso) | K7: TR-RN-004, TR-RN-001 | L7: Unidad operativa activa asignable a usuarios y numeración | M7: Must | N7: MVP | O7: TR-P01 | P7: TR-ORG, TR-CAT | Q7: TR-RNF-010, TR-RNF-027 | R7: No | S7: =COUNTIF('Criterios GWT'!B:B,A7) -> 3
A8: TR-RF-005 | B8: MOD-01 · Organización y suscripciones (TR-ORG) | C8: APP-01 · Consola de plataforma | D8: Gestionar suscripción de producto | E8: El sistema debe permitir al administrador de plataforma crear y modificar la suscripción de un tenant a un producto, indicando edición, plan, límites de sucursales y usuarios y vigencia, y propagar el cambio a permisos y cuotas. | F8: Administrador de plataforma | G8: plat.suscripcion.gestionar | H8: El tenant existe y no está en BAJA. | I8: 1. El actor abre el tenant y selecciona el producto. 2. Define edición, plan, límites y fecha de vigencia. 3. El sistema valida que los nuevos límites no sean menores que el uso actual. 4. El sistema guarda, invalida la caché de permisos y publica suscripcion.cambiada. | J8: producto_codigo (REST|PSI|COL|LIB|GYM|CLI|DOC|ECO|LEX); edicion (texto 0-30); plan (BASICO|PRO|EMPRESA); estado (PRUEBA|ACTIVA|VENCIDA|CANCELADA); limite_sucursales (entero ≥ 1 o vacío); limite_usuarios (entero ≥ 1 o vacío); vigente_hasta (fecha) | K8: TR-RN-006 | L8: Suscripción actualizada con efecto inmediato en permisos, cuotas y SLA | M8: Must | N8: MVP | O8: TR-P01, TR-P05 | P8: TR-ORG, TR-SEG, TR-EVT | Q8: TR-RNF-101, TR-RNF-027 | R8: No | S8: =COUNTIF('Criterios GWT'!B:B,A8) -> 3
A9: TR-RF-006 | B9: MOD-01 · Organización y suscripciones (TR-ORG) | C9: APP-01 · Consola de plataforma | D9: Cambiar estado del tenant | E9: El sistema debe permitir suspender, reactivar o dar de baja un tenant registrando motivo obligatorio, aplicando las restricciones del estado y notificando al propietario. | F9: Administrador de plataforma | G9: plat.tenant.cambiar_estado | H9: El actor tiene MFA vigente; el tenant existe. | I9: 1. El actor selecciona el nuevo estado e ingresa el motivo. 2. El sistema solicita confirmación explícita. 3. El sistema valida la transición permitida (TR-RN-005). 4. El sistema aplica el estado, cierra sesiones si es SUSPENDIDO o BAJA, registra auditoría y notifica al propietario. | J9: estado_nuevo (ACTIVO|SUSPENDIDO|BAJA); motivo (texto 10-500, obligatorio); fecha_efectiva (fecha-hora, por defecto ahora) | K9: TR-RN-005, TR-RN-009 | L9: Tenant en el nuevo estado con restricciones aplicadas y notificación enviada | M9: Must | N9: MVP | O9: TR-P01, TR-P05 | P9: TR-ORG, TR-SEG, TR-AUD, TR-NOT | Q9: TR-RNF-021, TR-RNF-013 | R9: No | S9: =COUNTIF('Criterios GWT'!B:B,A9) -> 3
A10: TR-RF-007 | B10: MOD-01 · Organización y suscripciones (TR-ORG) | C10: APP-03 · API de servicios de plataforma | D10: Controlar vencimiento de prueba y suscripción | E10: El sistema debe ejecutar diariamente el control de vencimientos: avisar al propietario 7, 3 y 1 días antes, pasar la suscripción a VENCIDA al vencer y suspender el tenant tras el periodo de gracia configurado. | F10: Planificador de tareas | G10: plat.sistema.job | H10: El job programado está activo; existen suscripciones con vigente_hasta. | I10: 1. El planificador ejecuta el control a las 06:00 hora de Lima. 2. El sistema identifica suscripciones que vencen en 7, 3 y 1 días y envía avisos. 3. Las suscripciones vencidas pasan a VENCIDA y se publica suscripcion.vencida. 4. Si el periodo de gracia (parámetro plat.suscripcion.dias_gracia) terminó sin pago, se suspende el tenant. | J10: dias_gracia (parámetro NUMERO, por defecto 5); fecha_ejecucion (fecha); resultados (lista de tenant, producto, acción) | K10: TR-RN-005, TR-RN-006 | L10: Suscripciones y tenants con estado actualizado y avisos enviados | M10: Must | N10: MVP | O10: TR-P01, TR-P05 | P10: TR-ORG, TR-NOT, TR-CFG, TR-EVT | Q10: TR-RNF-005, TR-RNF-008 | R10: No | S10: =COUNTIF('Criterios GWT'!B:B,A10) -> 3
A11: TR-RF-008 | B11: MOD-02 · Seguridad y accesos (TR-SEG) | C11: APP-03 · API de servicios de plataforma | D11: Aplicar manifiesto funcional del producto | E11: El sistema debe aplicar en cada despliegue el manifiesto declarativo de un producto (módulos, opciones de menú, permisos con alcance mínimo y sensibilidad, roles predefinidos, parámetros, indicadores y reportes) de forma idempotente. | F11: Planificador de tareas, Administrador de plataforma | G11: plat.manifiesto.aplicar | H11: El pipeline de despliegue dispone del manifiesto versionado del producto. | I11: 1. El pipeline envía el manifiesto con su versión. 2. El sistema valida su esquema y que los códigos de permiso cumplan producto.recurso.accion. 3. El sistema calcula diferencias contra lo registrado. 4. Inserta o actualiza módulos, opciones, permisos y roles predefinidos; marca como obsoletos los retirados. 5. Registra la versión aplicada y publica manifiesto.aplicado. | J11: producto_codigo (5 caracteres); version (semver); modulos[]; opciones[] (codigo, ruta, icono, permisos requeridos); permisos[] (codigo, descripcion, alcance_minimo, sensible); roles_predefinidos[]; parametros[]; indicadores[]; reportes[] | K11: TR-RN-007 | L11: Catálogo funcional del producto sincronizado con la versión desplegada | M11: Must | N11: MVP | O11: TR-P02, TR-P03 | P11: TR-SEG, TR-CFG, TR-OBS, TR-REP, TR-EVT | Q11: TR-RNF-120, TR-RNF-119, TR-RNF-024 | R11: No | S11: =COUNTIF('Criterios GWT'!B:B,A11) -> 3
A12: TR-RF-009 | B12: MOD-02 · Seguridad y accesos (TR-SEG) | C12: APP-02 · Administración del cliente (embebible) | D12: Invitar usuario al tenant | E12: El sistema debe permitir al administrador del cliente invitar a una persona por correo para que se una al tenant, indicando el perfil o rol inicial y su alcance, respetando el límite de usuarios del plan. | F12: Administrador del cliente | G12: plat.usuario.invitar | H12: El actor tiene alcance suficiente para el alcance que otorga; el plan no alcanzó su límite de usuarios. | I12: 1. El actor ingresa correo, nombre y perfil o rol con alcance. 2. El sistema verifica el límite de usuarios del plan. 3. Si el correo no existe en seg.usuario lo crea; crea la membresía en estado INVITADO y la asignación propuesta. 4. El sistema envía la invitación con enlace de un solo uso válido por 72 horas. | J12: correo (correo válido, obligatorio); nombre (texto 3-150); perfil_id o rol_id (uno obligatorio); alcance (TENANT|EMPRESA|SUCURSAL|UNIDAD); empresa_id/sucursal_id/unidad_id (según alcance); vigente_hasta (fecha opcional) | K12: TR-RN-006, TR-RN-008 | L12: Membresía INVITADO creada e invitación enviada | M12: Must | N12: MVP | O12: TR-P02 | P12: TR-SEG, TR-NOT, TR-ORG | Q12: TR-RNF-009, TR-RNF-013 | R12: No | S12: =COUNTIF('Criterios GWT'!B:B,A12) -> 3
A13: TR-RF-010 | B13: MOD-02 · Seguridad y accesos (TR-SEG) | C13: APP-05 · Librerías Angular compartidas y shell del portal | D13: Aceptar invitación y vincular identidad | E13: El sistema debe permitir que el invitado acepte la invitación autenticándose en el IdP (OIDC) y que su identificador (sub) quede vinculado a su usuario, activando la membresía. | F13: Usuario operativo del producto, Proveedor de identidad OIDC (IdP) | G13: publico.invitacion.aceptar | H13: La invitación está vigente y no fue usada. | I13: 1. El invitado abre el enlace de invitación. 2. El shell redirige al IdP para iniciar sesión o crear la cuenta. 3. El IdP devuelve el token con sub y correo verificado. 4. El sistema verifica que el correo coincida con la invitación y activa la membresía y su asignación. 5. El sistema registra el evento ASIGNACION_OTORGADA. | J13: token_invitacion (cadena de un solo uso); sub (uuid del IdP); correo_verificado (booleano) | K13: TR-RN-008 | L13: Membresía ACTIVA y usuario con acceso al producto | M13: Must | N13: MVP | O13: TR-P02 | P13: TR-SEG, TR-AUD | Q13: TR-RNF-009, TR-RNF-014 | R13: No | S13: =COUNTIF('Criterios GWT'!B:B,A13) -> 3
A14: TR-RF-011 | B14: MOD-02 · Seguridad y accesos (TR-SEG) | C14: APP-02 · Administración del cliente (embebible) | D14: Gestionar roles propios del tenant | E14: El sistema debe permitir crear, copiar desde un rol predefinido, editar e inactivar roles propios de un producto, seleccionando sus permisos del catálogo del producto; los roles predefinidos no son editables. | F14: Administrador del cliente | G14: plat.rol.gestionar | H14: El tenant tiene suscripción vigente al producto del rol. | I14: 1. El actor elige el producto y crea un rol nuevo o copia uno predefinido. 2. Marca los permisos del árbol módulo → opción → permiso. 3. El sistema valida que todos los permisos pertenezcan al producto. 4. El sistema guarda el rol, invalida la caché de permisos de los usuarios afectados y registra auditoría. | J14: producto_codigo (obligatorio); codigo (texto 3-50, único por tenant); nombre (texto 3-100); permisos[] (códigos del producto); activo (booleano) | K14: TR-RN-007, TR-RN-009 | L14: Rol propio disponible para asignación | M14: Must | N14: MVP | O14: TR-P02 | P14: TR-SEG, TR-AUD | Q14: TR-RNF-101, TR-RNF-122, TR-RNF-013 | R14: No | S14: =COUNTIF('Criterios GWT'!B:B,A14) -> 3
A15: TR-RF-012 | B15: MOD-02 · Seguridad y accesos (TR-SEG) | C15: APP-02 · Administración del cliente (embebible) | D15: Gestionar perfiles de puesto | E15: El sistema debe permitir definir perfiles de puesto que agrupen roles de uno o varios productos contratados, para asignar con una sola operación el acceso completo de un puesto. | F15: Administrador del cliente | G15: plat.perfil.gestionar | H15: Existen roles activos de los productos contratados. | I15: 1. El actor crea el perfil con código y nombre. 2. Selecciona uno o más roles de los productos contratados. 3. El sistema guarda el perfil y recalcula permisos de los usuarios que lo tienen asignado. | J15: codigo (texto 3-50, único por tenant); nombre (texto 3-100); roles[] (uuid de roles activos) | K15: TR-RN-007 | L15: Perfil disponible para asignación | M15: Should | N15: MVP | O15: TR-P02 | P15: TR-SEG | Q15: TR-RNF-101, TR-RNF-027 | R15: No | S15: =COUNTIF('Criterios GWT'!B:B,A15) -> 2
... A20: TR-RF-017 | B20: MOD-02 · Seguridad y accesos (TR-SEG) | C20: APP-03 · API de servicios de plataforma | D20: Exigir MFA para permisos sensibles | E20: El sistema debe exigir autenticación multifactor reciente (máximo 15 minutos) antes de ejecutar cualquier acción cuyo permiso esté marcado como sensible, solicitando la elevación al IdP cuando no esté vigente. | F20: Usuario operativo del producto, Proveedor de identidad OIDC (IdP) | G20: plat.mfa.elevar | H20: El permiso requerido tiene sensible = true en el manifiesto. | I20: 1. El guard detecta que la acción requiere un permiso sensible. 2. Verifica el claim de hora de MFA (amr/auth_time) del token. 3. Si supera 15 minutos, responde 401 con el desafío step-up. 4. El shell redirige al IdP para el segundo factor y reintenta la acción con el nuevo token. 5. La acción ejecutada se audita con indicador de MFA. | J20: permiso (código sensible); auth_time (epoch del IdP); amr (incluye otp o webauthn) | K20: TR-RN-009 | L20: Acción ejecutada con MFA vigente o rechazada con desafío | M20: Must | N20: MVP | O20: TR-P02 | P20: TR-SEG, TR-AUD | Q20: TR-RNF-009, TR-RNF-013 | R20: No | S20: =COUNTIF('Criterios GWT'!B:B,A20) -> 2
A21: TR-RF-018 | B21: MOD-02 · Seguridad y accesos (TR-SEG) | C21: APP-02 · Administración del cliente (embebible) | D21: Gestionar sesiones activas | E21: El sistema debe permitir al administrador del cliente ver las sesiones activas de los usuarios de su tenant (dispositivo, IP, último uso) y cerrarlas de forma remota, y al usuario ver y cerrar las propias. | F21: Administrador del cliente, Usuario operativo del producto | G21: plat.sesion.gestionar | H21: El IdP expone la gestión de sesiones del realm o proyecto. | I21: 1. El actor abre la lista de sesiones filtrada por usuario o sucursal. 2. El sistema consulta al IdP y la enriquece con el último contexto de sucursal. 3. El actor selecciona una sesión y la cierra. 4. El sistema revoca los tokens de renovación y registra el evento. | J21: usuario (texto); dispositivo (texto); ip (inet); inicio (fecha-hora); ultimo_uso (fecha-hora); sucursal (texto) | L21: Sesión cerrada y usuario obligado a autenticarse nuevamente | M21: Should | N21: R2 | O21: TR-P02 | P21: TR-SEG, TR-AUD | Q21: TR-RNF-014, TR-RNF-013 | R21: No | S21: =COUNTIF('Criterios GWT'!B:B,A21) -> 2
A22: TR-RF-019 | B22: MOD-02 · Seguridad y accesos (TR-SEG) | C22: APP-02 · Administración del cliente (embebible) | D22: Consultar bitácora de seguridad | E22: El sistema debe permitir consultar la bitácora de eventos de seguridad del tenant (inicios de sesión, accesos denegados, asignaciones otorgadas o revocadas, accesos de soporte) con filtros y exportación. | F22: Administrador del cliente, Responsable de datos personales del cliente | G22: plat.seguridad.bitacora | H22: Existen eventos en seg.evento_seguridad para el tenant. | I22: 1. El actor define filtros de fecha, usuario y tipo de evento. 2. El sistema devuelve la lista paginada ordenada por fecha descendente. 3. El actor abre el detalle con IP y datos del evento o exporta a Excel. | J22: fecha_desde, fecha_hasta (fecha); usuario (texto); tipo (LOGIN|ACCESO_DENEGADO|ASIGNACION_OTORGADA|ASIGNACION_REVOCADA|ACCESO_SOPORTE) | K22: TR-RN-047 | L22: Listado paginado de eventos y exportación auditada | M22: Should | N22: MVP | O22: TR-P02, TR-P11 | P22: TR-SEG, TR-AUD, TR-REP | Q22: TR-RNF-002, TR-RNF-013 | R22: No | S22: =COUNTIF('Criterios GWT'!B:B,A22) -> 2
A23: TR-RF-020 | B23: MOD-02 · Seguridad y accesos (TR-SEG) | C23: APP-02 · Administración del cliente (embebible) | D23: Autorizar acceso temporal de soporte | E23: El sistema debe permitir al administrador del cliente autorizar que un agente de soporte acceda a su tenant con motivo, ticket asociado, alcance y vigencia máxima de 4 horas, y al agente operar con un banner visible y auditoría de cada acción. | F23: Administrador del cliente, Agente de soporte (N1/N2) | G23: plat.soporte.autorizar | H23: Existe un ticket abierto del tenant asignado al agente. | I23: 1. El agente solicita acceso desde el ticket indicando motivo y alcance de solo lectura o lectura y escritura. 2. El administrador del cliente recibe la solicitud y la aprueba con vigencia de hasta 4 horas. 3. El sistema crea una membresía temporal tipo SOPORTE y registra ACCESO_SOPORTE. 4. El agente opera con un banner «Sesión de soporte»; cada acción se audita con el número de ticket. 5. Al vencer la vigencia o cerrar el ticket, el acceso se revoca automáticamente. | J23: ticket (SOP-######); motivo (texto 10-300); modo (LECTURA|ESCRITURA); vigencia_horas (1-4); aprobado_por (uuid) | K23: TR-RN-011 | L23: Acceso de soporte vigente, visible y auditado, revocado automáticamente | M23: Must | N23: MVP | O23: TR-P02, TR-P08 | P23: TR-SEG, TR-SOP, TR-AUD, TR-NOT | Q23: TR-RNF-110, TR-RNF-013 | R23: No | S23: =COUNTIF('Criterios GWT'!B:B,A23) -> 3
A24: TR-RF-021 | B24: MOD-02 · Seguridad y accesos (TR-SEG) | C24: APP-02 · Administración del cliente (embebible) | D24: Transferir propiedad del tenant | E24: El sistema debe permitir al propietario transferir la propiedad del tenant a otro miembro activo, con confirmación por MFA de ambos, conservando la trazabilidad. | F24: Administrador del cliente | G24: plat.tenant.transferir | H24: El destinatario es miembro ACTIVO del tenant. | I24: 1. El propietario selecciona al nuevo propietario y confirma con MFA. 2. El sistema notifica al destinatario, que acepta con MFA. 3. El sistema marca al destinatario como propietario y, si se indicó, retira la marca al anterior. 4. Registra el cambio en auditoría y notifica a ambos. | J24: nuevo_propietario_id (uuid); conservar_propiedad_actual (booleano); motivo (texto 5-300) | K24: TR-RN-010, TR-RN-009 | L24: Propiedad transferida con aceptación del destinatario | M24: Could | N24: R2 | O24: TR-P01, TR-P02 | P24: TR-SEG, TR-AUD, TR-NOT | Q24: TR-RNF-009, TR-RNF-021 | R24: No | S24: =COUNTIF('Criterios GWT'!B:B,A24) -> 2
A25: TR-RF-022 | B25: MOD-03 · Catálogos y tablas maestras (TR-CAT) | C25: APP-01 · Consola de plataforma | D25: Administrar catálogos globales | E25: El sistema debe permitir al administrador de plataforma crear y editar la definición de catálogos (código, nombre, alcance GLOBAL, TENANT o MIXTO, fuente y si es editable por el tenant), incrementando la versión ante cada cambio. | F25: Administrador de plataforma | G25: plat.catalogo.gestionar | H25: El actor tiene sesión en la consola de plataforma. | I25: 1. El actor crea o edita un catálogo. 2. El sistema valida unicidad del código y coherencia entre alcance y editable_por_tenant. 3. Guarda, incrementa la versión y publica catalogo.actualizado. 4. El sistema invalida la caché del catálogo en Redis. | J25: codigo (texto 3-60, mayúsculas y guion bajo, único); nombre (texto 3-150); alcance (GLOBAL|TENANT|MIXTO); fuente (texto 0-150, p. ej. «SUNAT Catálogo 06»); editable_por_tenant (booleano); version (entero autoincremental) | K25: TR-RN-012 | L25: Catálogo definido y versionado | M25: Must | N25: MVP | O25: TR-P03 | P25: TR-CAT, TR-EVT | Q25: TR-RNF-102, TR-RNF-027 | R25: No | S25: =COUNTIF('Criterios GWT'!B:B,A25) -> 2
A26: TR-RF-023 | B26: MOD-03 · Catálogos y tablas maestras (TR-CAT) | C26: APP-01 · Consola de plataforma | D26: Administrar ítems de catálogo con vigencia | E26: El sistema debe permitir registrar, editar, inactivar y cerrar la vigencia de ítems de un catálogo con código, código externo oficial, nombre, abreviatura, orden y atributos JSON, sin eliminar ítems referenciados. | F26: Administrador de plataforma, Administrador del cliente | G26: plat.catalogo.item_gestionar | H26: El catálogo existe; para ítems propios del tenant el catálogo es MIXTO o TENANT. | I26: 1. El actor abre el catálogo y agrega o edita un ítem. 2. Ingresa código, código externo, nombre, orden, atributos y vigencia. 3. El sistema valida unicidad por catálogo y tenant (TR-RN-013). 4. Ante eliminación de ítem referenciado, el sistema ofrece cerrar la vigencia. 5. Guarda, incrementa la versión del catálogo e invalida la caché. | J26: codigo (texto 1-40); codigo_externo (texto 0-40); nombre (texto 1-200); abreviatura (0-30); orden (entero); atributos (JSON: longitud, regex, valida_reniec, mascara); vigente_desde (fecha); vigente_hasta (fecha opcional ≥ desde); activo (booleano) | K26: TR-RN-012, TR-RN-013 | L26: Ítem vigente o cerrado sin pérdida de referencias | M26: Must | N26: MVP | O26: TR-P03 | P26: TR-CAT, TR-EVT | Q26: TR-RNF-102, TR-RNF-021 | R26: No | S26: =COUNTIF('Criterios GWT'!B:B,A26) -> 3
A27: TR-RF-024 | B27: MOD-03 · Catálogos y tablas maestras (TR-CAT) | C27: APP-03 · API de servicios de plataforma | D27: Consultar ítems de catálogo con caché | E27: El sistema debe exponer GET /v1/catalogos/{codigo}/items que devuelva los ítems vigentes y visibles para el tenant (globales más propios con ajustes aplicados), con ETag, caché Redis y respuesta 304 cuando no hay cambios. | F27: Módulo de producto consumidor, Usuario operativo del producto | G27: plat.catalogo.leer | H27: El request tiene contexto de tenant. | I27: 1. El cliente solicita los ítems con If-None-Match opcional. 2. El sistema busca en Redis la clave cat:{codigo}:{tenant}:{version}. 3. Si no existe, ejecuta cat.items y guarda el resultado con TTL. 4. Devuelve 200 con ETag o 304 si coincide. | J27: codigo (ruta); If-None-Match (cabecera opcional); respuesta: item_id, codigo, codigo_externo, nombre (alias si existe), atributos, orden | K27: TR-RN-012 | L27: Lista ordenada de ítems vigentes o 304 | M27: Must | N27: MVP | O27: TR-P03 | P27: TR-CAT | Q27: TR-RNF-102, TR-RNF-002 | R27: No | S27: =COUNTIF('Criterios GWT'!B:B,A27) -> 3
A28: TR-RF-025 | B28: MOD-03 · Catálogos y tablas maestras (TR-CAT) | C28: APP-02 · Administración del cliente (embebible) | D28: Personalizar ítems globales por tenant | E28: El sistema debe permitir al administrador del cliente ocultar, reordenar y renombrar (alias) ítems globales de catálogos MIXTO sin alterar el ítem global ni afectar a otros tenants. | F28: Administrador del cliente | G28: plat.catalogo.personalizar | H28: El catálogo tiene alcance MIXTO o editable_por_tenant = verdadero. | I28: 1. El actor abre el catálogo y ve los ítems globales y propios. 2. Cambia visibilidad, orden o alias de un ítem global. 3. El sistema guarda el ajuste en cat.catalogo_item_tenant e invalida la caché del tenant. | J28: item_id (uuid); visible (booleano); orden (entero opcional); alias (texto 0-200) | K28: TR-RN-012 | L28: Lista del tenant con ajustes aplicados | M28: Should | N28: MVP | O28: TR-P03 | P28: TR-CAT | Q28: TR-RNF-027, TR-RNF-102 | R28: No | S28: =COUNTIF('Criterios GWT'!B:B,A28) -> 2
A29: TR-RF-026 | B29: MOD-03 · Catálogos y tablas maestras (TR-CAT) | C29: APP-02 · Administración del cliente (embebible) | D29: Registrar ítems propios del tenant | E29: El sistema debe permitir al administrador del cliente registrar, editar e inactivar ítems propios en catálogos MIXTO o TENANT (por ejemplo especialidades, categorías de producto, tipos de trámite). | F29: Administrador del cliente | G29: plat.catalogo.item_propio | H29: El catálogo es MIXTO o TENANT. | I29: 1. El actor agrega un ítem con código y nombre. 2. El sistema valida que el código no coincida con un ítem global ni propio existente. 3. Guarda con tenant_id del contexto e invalida la caché. | J29: codigo (texto 1-40); nombre (texto 1-200); orden (entero); atributos (JSON opcional); activo (booleano) | K29: TR-RN-012, TR-RN-013 | L29: Ítem propio disponible solo para el tenant | M29: Must | N29: MVP | O29: TR-P03 | P29: TR-CAT | Q29: TR-RNF-027, TR-RNF-010 | R29: No | S29: =COUNTIF('Criterios GWT'!B:B,A29) -> 2
A30: TR-RF-027 | B30: MOD-03 · Catálogos y tablas maestras (TR-CAT) | C30: APP-03 · API de servicios de plataforma | D30: Validar valor contra catálogo | E30: El sistema debe proveer el puerto CatalogoPort.validarItem(catalogo, codigo) que confirme si un código es vigente y visible para el tenant y devuelva sus atributos para validaciones del producto. | F30: Módulo de producto consumidor | G30: plat.catalogo.leer | H30: El módulo de producto tiene contexto de tenant. | I30: 1. El módulo invoca validarItem con catálogo y código. 2. El sistema resuelve desde caché los ítems del tenant. 3. Devuelve válido con atributos o inválido con motivo (inexistente, inactivo, fuera de vigencia, oculto). | J30: catalogo (texto); codigo (texto); respuesta: valido (booleano), motivo (texto), atributos (JSON) | K30: TR-RN-012, TR-RN-013 | L30: Resultado de validación con atributos | M30: Must | N30: MVP | O30: TR-P03, TR-P10 | P30: TR-CAT | Q30: TR-RNF-102, TR-RNF-012 | R30: No | S30: =COUNTIF('Criterios GWT'!B:B,A30) -> 2
